Workbook
Name Slicer_Category: #N/A
Name Slicer_Region: #N/A
Name Slicer_Segment1: #N/A
Name Slicer_Years__Order_Date: #N/A

Sheet Sales Data
A1: Row ID | B1: Order ID | C1: Order Date | D1: Ship Date | E1: Ship Mode | F1: Customer ID | G1: Customer Name | H1: Segment | I1: Country | J1: City | K1: State | L1: Postal Code | M1: Region | N1: Product ID | O1: Category | P1: Sub-Category | Q1: Product Name | R1: Sales
A2: 1 | B2: CA-2017-152156 | C2: 43047 | D2: 43050 | E2: Second Class | F2: CG-12520 | G2: Claire Gute | H2: Consumer | I2: United States | J2: Henderson | K2: Kentucky | L2: 42420 | M2: South | N2: FUR-BO-10001798 | O2: Furniture | P2: Bookcases | Q2: Bush Somerset Collection Bookcase | R2: 261.96
A3: 2 | B3: CA-2017-152156 | C3: 43047 | D3: 43050 | E3: Second Class | F3: CG-12520 | G3: Claire Gute | H3: Consumer | I3: United States | J3: Henderson | K3: Kentucky | L3: 42420 | M3: South | N3: FUR-CH-10000454 | O3: Furniture | P3: Chairs | Q3: Hon Deluxe Fabric Upholstered Stacking Chairs, Rounded Back | R3: 731.94
A4: 3 | B4: CA-2017-138688 | C4: 42898 | D4: 42902 | E4: Second Class | F4: DV-13045 | G4: Darrin Van Huff | H4: Corporate | I4: United States | J4: Los Angeles | K4: California | L4: 90036 | M4: West | N4: OFF-LA-10000240 | O4: Office Supplies | P4: Labels | Q4: Self-Adhesive Address Labels for Typewriters by Universal | R4: 14.62
A5: 4 | B5: US-2016-108966 | C5: 42654 | D5: 42661 | E5: Standard Class | F5: SO-20335 | G5: Sean O'Donnell | H5: Consumer | I5: United States | J5: Fort Lauderdale | K5: Florida | L5: 33311 | M5: South | N5: FUR-TA-10000577 | O5: Furniture | P5: Tables | Q5: Bretford CR4500 Series Slim Rectangular Table | R5: 957.5775
A6: 5 | B6: US-2016-108966 | C6: 42654 | D6: 42661 | E6: Standard Class | F6: SO-20335 | G6: Sean O'Donnell | H6: Consumer | I6: United States | J6: Fort Lauderdale | K6: Florida | L6: 33311 | M6: South | N6: OFF-ST-10000760 | O6: Office Supplies | P6: Storage | Q6: Eldon Fold 'N Roll Cart System | R6: 22.368
A7: 6 | B7: CA-2015-115812 | C7: 42164 | D7: 42169 | E7: Standard Class | F7: BH-11710 | G7: Brosina Hoffman | H7: Consumer | I7: United States | J7: Los Angeles | K7: California | L7: 90032 | M7: West | N7: FUR-FU-10001487 | O7: Furniture | P7: Furnishings | Q7: Eldon Expressions Wood and Plastic Desk Accessories, Cherry Wood | R7: 48.86
A8: 7 | B8: CA-2015-115812 | C8: 42164 | D8: 42169 | E8: Standard Class | F8: BH-11710 | G8: Brosina Hoffman | H8: Consumer | I8: United States | J8: Los Angeles | K8: California | L8: 90032 | M8: West | N8: OFF-AR-10002833 | O8: Office Supplies | P8: Art | Q8: Newell 322 | R8: 7.28
A9: 8 | B9: CA-2015-115812 | C9: 42164 | D9: 42169 | E9: Standard Class | F9: BH-11710 | G9: Brosina Hoffman | H9: Consumer | I9: United States | J9: Los Angeles | K9: California | L9: 90032 | M9: West | N9: TEC-PH-10002275 | O9: Technology | P9: Phones | Q9: Mitel 5320 IP Phone VoIP phone | R9: 907.152
A10: 9 | B10: CA-2015-115812 | C10: 42164 | D10: 42169 | E10: Standard Class | F10: BH-11710 | G10: Brosina Hoffman | H10: Consumer | I10: United States | J10: Los Angeles | K10: California | L10: 90032 | M10: West | N10: OFF-BI-10003910 | O10: Office Supplies | P10: Binders | Q10: DXL Angle-View Binders with Locking Rings by Samsill | R10: 18.504
A11: 10 | B11: CA-2015-115812 | C11: 42164 | D11: 42169 | E11: Standard Class | F11: BH-11710 | G11: Brosina Hoffman | H11: Consumer | I11: United States | J11: Los Angeles | K11: California | L11: 90032 | M11: West | N11: OFF-AP-10002892 | O11: Office Supplies | P11: Appliances | Q11: Belkin F5C206VTEL 6 Outlet Surge | R11: 114.9
A12: 11 | B12: CA-2015-115812 | C12: 42164 | D12: 42169 | E12: Standard Class | F12: BH-11710 | G12: Brosina Hoffman | H12: Consumer | I12: United States | J12: Los Angeles | K12: California | L12: 90032 | M12: West | N12: FUR-TA-10001539 | O12: Furniture | P12: Tables | Q12: Chromcraft Rectangular Conference Tables | R12: 1706.184
A13: 12 | B13: CA-2015-115812 | C13: 42164 | D13: 42169 | E13: Standard Class | F13: BH-11710 | G13: Brosina Hoffman | H13: Consumer | I13: United States | J13: Los Angeles | K13: California | L13: 90032 | M13: West | N13: TEC-PH-10002033 | O13: Technology | P13: Phones | Q13: Konftel 250 Conference¬†phone¬†- Charcoal black | R13: 911.424
... A2235: 2234 | B2235: CA-2016-123232 | C2235: 42718 | D2235: 42720 | E2235: Second Class | F2235: DJ-13630 | G2235: Doug Jacobs | H2235: Consumer | I2235: United States | J2235: Portland | K2235: Oregon | L2235: 97206 | M2235: West | N2235: TEC-PH-10001051 | O2235: Technology | P2235: Phones | Q2235: HTC One | R2235: 319.968
A2236: 2235 | B2236: CA-2018-104066 | C2236: 43439 | D2236: 43444 | E2236: Standard Class | F2236: QJ-19255 | G2236: Quincy Jones | H2236: Corporate | I2236: United States | J2236: Burlington | K2236: Vermont | M2236: East | N2236: TEC-AC-10001013 | O2236: Technology | P2236: Accessories | Q2236: Logitech ClearChat Comfort/USB Headset H390 | R2236: 205.03
A2237: 2236 | B2237: CA-2016-145849 | C2237: 42628 | D2237: 42630 | E2237: Second Class | F2237: CT-11995 | G2237: Carol Triggs | H2237: Consumer | I2237: United States | J2237: Indianapolis | K2237: Indiana | L2237: 46203 | M2237: Central | N2237: OFF-ST-10000025 | O2237: Office Supplies | P2237: Storage | Q2237: Fellowes Stor/Drawer Steel Plus Storage Drawers | R2237: 190.86
A2238: 2237 | B2238: CA-2016-145849 | C2238: 42628 | D2238: 42630 | E2238: Second Class | F2238: CT-11995 | G2238: Carol Triggs | H2238: Consumer | I2238: United States | J2238: Indianapolis | K2238: Indiana | L2238: 46203 | M2238: Central | N2238: OFF-AR-10000817 | O2238: Office Supplies | P2238: Art | Q2238: Manco Dry-Lighter Erasable Highlighter | R2238: 24.32
A2239: 2238 | B2239: CA-2017-122322 | C2239: 42931 | D2239: 42937 | E2239: Standard Class | F2239: RH-19510 | G2239: Rick Huthwaite | H2239: Home Office | I2239: United States | J2239: Provo | K2239: Utah | L2239: 84604 | M2239: West | N2239: OFF-SU-10000952 | O2239: Office Supplies | P2239: Supplies | Q2239: Fiskars Home & Office Scissors | R2239: 44.4
A2240: 2239 | B2240: CA-2018-166849 | C2240: 43210 | D2240: 43216 | E2240: Standard Class | F2240: SJ-20125 | G2240: Sanjit Jacobs | H2240: Home Office | I2240: United States | J2240: Chicago | K2240: Illinois | L2240: 60610 | M2240: Central | N2240: FUR-FU-10004597 | O2240: Furniture | P2240: Furnishings | Q2240: Eldon Cleatmat Chair Mats for Medium Pile Carpets | R2240: 44.4
A2241: 2240 | B2241: CA-2017-146633 | C2241: 43054 | D2241: 43056 | E2241: Second Class | F2241: TG-21310 | G2241: Toby Gnade | H2241: Consumer | I2241: United States | J2241: Los Angeles | K2241: California | L2241: 90049 | M2241: West | N2241: OFF-BI-10003527 | O2241: Office Supplies | P2241: Binders | Q2241: Fellowes PB500 Electric Punch Plastic Comb Binding Machine with Manual Bind | R2241: 1016.792
A2242: 2241 | B2242: CA-2017-146633 | C2242: 43054 | D2242: 43056 | E2242: Second Class | F2242: TG-21310 | G2242: Toby Gnade | H2242: Consumer | I2242: United States | J2242: Los Angeles | K2242: California | L2242: 90049 | M2242: West | N2242: OFF-BI-10002982 | O2242: Office Supplies | P2242: Binders | Q2242: Avery Self-Adhesive Photo Pockets for Polaroid Photos | R2242: 38.136
A2243: 2242 | B2243: US-2017-126893 | C2243: 43065 | D2243: 43070 | E2243: Standard Class | F2243: CT-11995 | G2243: Carol Triggs | H2243: Consumer | I2243: United States | J2243: Philadelphia | K2243: Pennsylvania | L2243: 19134 | M2243: East | N2243: TEC-PH-10004165 | O2243: Technology | P2243: Phones | Q2243: Mitel MiVoice 5330e IP Phone | R2243: 494.982
A2244: 2243 | B2244: CA-2018-103380 | C2244: 43425 | D2244: 43429 | E2244: Standard Class | F2244: BF-11005 | G2244: Barry Franz | H2244: Home Office | I2244: United States | J2244: Pasadena | K2244: California | L2244: 91104 | M2244: West | N2244: OFF-ST-10003442 | O2244: Office Supplies | P2244: Storage | Q2244: Eldon Portable Mobile Manager | R2244: 56.56
A2245: 2244 | B2245: CA-2018-103380 | C2245: 43425 | D2245: 43429 | E2245: Standard Class | F2245: BF-11005 | G2245: Barry Franz | H2245: Home Office | I2245: United States | J2245: Pasadena | K2245: California | L2245: 91104 | M2245: West | N2245: OFF-AR-10003856 | O2245: Office Supplies | P2245: Art | Q2245: Newell 344 | R2245: 5.56
A2246: 2245 | B2246: CA-2018-103380 | C2246: 43425 | D2246: 43429 | E2246: Standard Class | F2246: BF-11005 | G2246: Barry Franz | H2246: Home Office | I2246: United States | J2246: Pasadena | K2246: California | L2246: 91104 | M2246: West | N2246: OFF-FA-10004248 | O2246: Office Supplies | P2246: Fasteners | Q2246: Advantus T-Pin Paper Clips | R2246: 9.02
A2247: 2246 | B2247: CA-2018-103380 | C2247: 43425 | D2247: 43429 | E2247: Standard Class | F2247: BF-11005 | G2247: Barry Franz | H2247: Home Office | I2247: United States | J2247: Pasadena | K2247: California | L2247: 91104 | M2247: West | N2247: OFF-AP-10001492 | O2247: Office Supplies | P2247: Appliances | Q2247: Acco Six-Outlet Power Strip, 4' Cord Length | R2247: 8.62
A2248: 2247 | B2248: CA-2018-103380 | C2248: 43425 | D2248: 43429 | E2248: Standard Class | F2248: BF-11005 | G2248: Barry Franz | H2248: Home Office | I2248: United States | J2248: Pasadena | K2248: California | L2248: 91104 | M2248: West | N2248: TEC-PH-10004165 | O2248: Technology | P2248: Phones | Q2248: Mitel MiVoice 5330e IP Phone | R2248: 659.976
... A5275: 5274 | B5275: US-2017-158309 | C5275: 43065 | D5275: 43068 | E5275: First Class | F5275: PA-19060 | G5275: Pete Armstrong | H5275: Home Office | I5275: United States | J5275: Miami | K5275: Florida | L5275: 33142 | M5275: South | N5275: OFF-BI-10000145 | O5275: Office Supplies | P5275: Binders | Q5275: Zipper Ring Binder Pockets | R5275: 3.744
A5276: 5275 | B5276: CA-2016-162887 | C5276: 42681 | D5276: 42683 | E5276: Second Class | F5276: SV-20785 | G5276: Stewart Visinsky | H5276: Consumer | I5276: United States | J5276: Burlington | K5276: Vermont | M5276: East | N5276: FUR-CH-10000595 | O5276: Furniture | P5276: Chairs | Q5276: Safco Contoured Stacking Chairs | R5276: 715.2
A5277: 5276 | B5277: CA-2018-147333 | C5277: 43448 | D5277: 43454 | E5277: Standard Class | F5277: KL-16555 | G5277: Kelly Lampkin | H5277: Corporate | I5277: United States | J5277: Fayetteville | K5277: Arkansas | L5277: 72701 | M5277: South | N5277: TEC-AC-10004469 | O5277: Technology | P5277: Accessories | Q5277: Microsoft Sculpt Comfort Mouse | R5277: 159.8
A5278: 5277 | B5278: CA-2018-147333 | C5278: 43448 | D5278: 43454 | E5278: Standard Class | F5278: KL-16555 | G5278: Kelly Lampkin | H5278: Corporate | I5278: United States | J5278: Fayetteville | K5278: Arkansas | L5278: 72701 | M5278: South | N5278: TEC-AC-10003038 | O5278: Technology | P5278: Accessories | Q5278: Kingston Digital DataTraveler 16GB USB 2.0 | R5278: 44.75
A5279: 5278 | B5279: CA-2015-113859 | C5279: 42260 | D5279: 42264 | E5279: Standard Class | F5279: BC-11125 | G5279: Becky Castell | H5279: Home Office | I5279: United States | J5279: Odessa | K5279: Texas | L5279: 79762 | M5279: Central | N5279: FUR-CH-10004698 | O5279: Furniture | P5279: Chairs | Q5279: Padded Folding Chairs, Black, 4/Carton | R5279: 340.116
A5280: 5279 | B5280: CA-2015-159681 | C5280: 42345 | D5280: 42351 | E5280: Standard Class | F5280: PO-18850 | G5280: Patrick O'Brill | H5280: Consumer | I5280: United States | J5280: Virginia Beach | K5280: Virginia | L5280: 23464 | M5280: South | N5280: OFF-PA-10003641 | O5280: Office Supplies | P5280: Paper | Q5280: Xerox 1909 | R5280: 105.52
A5281: 5280 | B5281: US-2018-104094 | C5281: 43350 | D5281: 43354 | E5281: Standard Class | F5281: AG-10675 | G5281: Anna Gayman | H5281: Consumer | I5281: United States | J5281: Milwaukee | K5281: Wisconsin | L5281: 53209 | M5281: Central | N5281: TEC-AC-10002134 | O5281: Technology | P5281: Accessories | Q5281: Rosewill 107 Normal Keys USB Wired Standard Keyboard | R5281: 13.48
A5282: 5281 | B5282: CA-2018-152709 | C5282: 43380 | D5282: 43385 | E5282: Standard Class | F5282: DB-13210 | G5282: Dean Braden | H5282: Consumer | I5282: United States | J5282: Detroit | K5282: Michigan | L5282: 48234 | M5282: Central | N5282: OFF-ST-10001837 | O5282: Office Supplies | P5282: Storage | Q5282: SAFCO Mobile Desk Side File, Wire Frame | R5282: 85.52
A5283: 5282 | B5283: CA-2016-105158 | C5283: 42618 | D5283: 42623 | E5283: Standard Class | F5283: SP-20860 | G5283: Sung Pak | H5283: Corporate | I5283: United States | J5283: Rochester | K5283: Minnesota | L5283: 55901 | M5283: Central | N5283: FUR-FU-10001706 | O5283: Furniture | P5283: Furnishings | Q5283: Longer-Life Soft White Bulbs | R5283: 6.16
A5284: 5283 | B5284: CA-2016-105158 | C5284: 42618 | D5284: 42623 | E5284: Standard Class | F5284: SP-20860 | G5284: Sung Pak | H5284: Corporate | I5284: United States | J5284: Rochester | K5284: Minnesota | L5284: 55901 | M5284: Central | N5284: OFF-PA-10001970 | O5284: Office Supplies | P5284: Paper | Q5284: Xerox 1881 | R5284: 36.84
A5285: 5284 | B5285: CA-2015-133424 | C5285: 42093 | D5285: 42098 | E5285: Standard Class | F5285: Dl-13600 | G5285: Dorris liebe | H5285: Corporate | I5285: United States | J5285: Seattle | K5285: Washington | L5285: 98105 | M5285: West | N5285: OFF-ST-10002957 | O5285: Office Supplies | P5285: Storage | Q5285: Sterilite Show Offs Storage Containers | R5285: 15.84
A5286: 5285 | B5286: CA-2015-133424 | C5286: 42093 | D5286: 42098 | E5286: Standard Class | F5286: Dl-13600 | G5286: Dorris liebe | H5286: Corporate | I5286: United States | J5286: Seattle | K5286: Washington | L5286: 98105 | M5286: West | N5286: OFF-LA-10002312 | O5286: Office Supplies | P5286: Labels | Q5286: Avery 490 | R5286: 44.4
A5287: 5286 | B5287: CA-2018-105991 | C5287: 43225 | D5287: 43226 | E5287: First Class | F5287: LH-17020 | G5287: Lisa Hazard | H5287: Consumer | I5287: United States | J5287: Louisville | K5287: Colorado | L5287: 80027 | M5287: West | N5287: OFF-EN-10002600 | O5287: Office Supplies | P5287: Envelopes | Q5287: Redi-Strip #10 Envelopes, 4 1/8 x 9 1/2 | R5287: 21.24
...

Sheet PivotTables
A3: Row Labels | B3: Sum of Sales | C3: Region (Clean) | D3: Sum of Sales | G3: Row Labels | H3: Count of Customer ID | I3: Category (Clean) | J3: Percentage of customers | L3: Sum of Sales | M3: Column Labels | Y3: Row Labels | Z3: Sum of Sales | AB3: Category | AC3: Sales | AE3: Row Labels | AF3: Count of Customer ID
A4: Central | B4: 492646.91 | C4: =OFFSET($A$4, ROW()-ROW($C$4),0) -> Central | D4: =OFFSET($B$4, ROW()-ROW($D$4),0) -> 492646.91 | G4: Furniture | H4: 0.21204082 | I4: =OFFSET($G$4, ROW()-ROW($I$4),0) -> Furniture | J4: =OFFSET($H$4, ROW()-ROW($J$4),0) -> 0.21204082 | L4: Row Labels | M4: 2015 | N4: 2016 | O4: 2017 | P4: 2018 | Q4: Grand Total | R4: Month | S4: 2015 | T4: 2016 | U4: 2017 | V4: 2018 | W4: Total (Monthly) | Y4: Furniture | Z4: 728658.58 | AB4: =OFFSET($Y$4, ROW()-ROW($AB$4),0) -> Furniture | AC4: =OFFSET($Z$4, ROW()-ROW($AC$4),0) -> 728658.58 | AE4: Central | AF4: 2277 | AG4: =OFFSET($AE$4, ROW()-ROW($AG$4),0) -> Central | AH4: =OFFSET($AF$4, ROW()-ROW($AH$4),0) -> 2277 | AJ4: Row Labels | AK4: Sum of Sales | AL4: Segment | AM4: Sales | AO4: Row Labels | AP4: Count of Customer ID | AU4: Row Labels | AV4: Sum of Sales | BA4: Count of Customer ID | BB4: Column Labels | BM4: Count of Customer ID | BN4: Column Labels | BS4: Row Labels | BT4: Sum of Sales | BW4: Row Labels | BX4: Sum of Sales | CA4: Row Labels | CB4: Sum of Sales
A5: East | B5: 669518.73 | C5: =OFFSET($A$4, ROW()-ROW($C$4),0) -> East | D5: =OFFSET($B$4, ROW()-ROW($D$4),0) -> 669518.73 | G5: Office Supplies | H5: 0.60295918 | I5: =OFFSET($G$4, ROW()-ROW($I$4),0) -> Office Supplies | J5: =OFFSET($H$4, ROW()-ROW($J$4),0) -> 0.60295918 | L5: Jan | M5: 14205.707 | N5: 18066.958 | O5: 18542.491 | P5: 43476.474 | Q5: 94291.63 | R5: =OFFSET($L$5, ROW()-ROW($R$5),0) -> Jan | S5: =OFFSET($M$5, ROW()-ROW($S$5),0) -> 14205.707 | T5: =OFFSET($N$5, ROW()-ROW($T$5),0) -> 18066.958 | U5: =OFFSET($O$5, ROW()-ROW($U$5),0) -> 18542.491 | V5: =OFFSET($P$5, ROW()-ROW($V$5),0) -> 43476.474 | W5: =OFFSET($Q$5, ROW()-ROW($W$5),0) -> 94291.63 | Y5: Office Supplies | Z5: 705422.33 | AB5: =OFFSET($Y$4, ROW()-ROW($AB$4),0) -> Office Supplies | AC5: =OFFSET($Z$4, ROW()-ROW($AC$4),0) -> 705422.33 | AE5: East | AF5: 2785 | AG5: =OFFSET($AE$4, ROW()-ROW($AG$4),0) -> East | AH5: =OFFSET($AF$4, ROW()-ROW($AH$4),0) -> 2785 | AJ5: Consumer | AK5: 0.50764619 | AL5: =OFFSET($AJ$5, ROW()-ROW($AL$5),0) -> Consumer | AM5: =OFFSET($AK$5, ROW()-ROW($AM$5),0) -> 0.50764619 | AO5: Furniture | AP5: 2078 | AU5: Phones | AV5: 327782.45 | AX5: =OFFSET($AU$5, ROW()-ROW($AX$5),0) -> Phones | AY5: =OFFSET($AV$5, ROW()-ROW($AY$5),0) -> 327782.45 | BA5: Row Labels | BB5: Furniture | BC5: Office Supplies | BD5: Technology | BE5: Grand Total | BH5: =OFFSET($BB$5, ROW()-ROW($BH$5),0) -> Furniture | BI5: =OFFSET($BC$5, ROW()-ROW($BI$5),0) -> Office Supplies | BJ5: =OFFSET($BD$5, ROW()-ROW($BJ$5),0) -> Technology | BK5: =OFFSET($BE$5, ROW()-ROW($BK$5),0) -> Grand Total | BM5: Row Labels | BN5: Consumer | BO5: Corporate | BP5: Home Office | BQ5: Grand Total | BS5: 2015 | BT5: 479856.21 | BW5: 2015 | BX5: 479856.21 | CA5: Central | CB5: 0.21783723
A6: South | B6: 389151.46 | C6: =OFFSET($A$4, ROW()-ROW($C$4),0) -> South | D6: =OFFSET($B$4, ROW()-ROW($D$4),0) -> 389151.46 | G6: Technology | H6: 0.185 | I6: =OFFSET($G$4, ROW()-ROW($I$4),0) -> Technology | J6: =OFFSET($H$4, ROW()-ROW($J$4),0) -> 0.185 | L6: Feb | M6: 4519.892 | N6: 11951.411 | O6: 22978.815 | P6: 19920.997 | Q6: 59371.115 | R6: =OFFSET($L$5, ROW()-ROW($R$5),0) -> Feb | S6: =OFFSET($M$5, ROW()-ROW($S$5),0) -> 4519.892 | T6: =OFFSET($N$5, ROW()-ROW($T$5),0) -> 11951.411 | U6: =OFFSET($O$5, ROW()-ROW($U$5),0) -> 22978.815 | V6: =OFFSET($P$5, ROW()-ROW($V$5),0) -> 19920.997 | W6: =OFFSET($Q$5, ROW()-ROW($W$5),0) -> 59371.115 | Y6: Technology | Z6: 827455.87 | AB6: =OFFSET($Y$4, ROW()-ROW($AB$4),0) -> Technology | AC6: =OFFSET($Z$4, ROW()-ROW($AC$4),0) -> 827455.87 | AE6: South | AF6: 1598 | AG6: =OFFSET($AE$4, ROW()-ROW($AG$4),0) -> South | AH6: =OFFSET($AF$4, ROW()-ROW($AH$4),0) -> 1598 | AJ6: Corporate | AK6: 0.30443638 | AL6: =OFFSET($AJ$5, ROW()-ROW($AL$5),0) -> Corporate | AM6: =OFFSET($AK$5, ROW()-ROW($AM$5),0) -> 0.30443638 | AO6: Office Supplies | AP6: 5909 | AU6: Chairs | AV6: 322822.73 | AX6: =OFFSET($AU$5, ROW()-ROW($AX$5),0) -> Chairs | AY6: =OFFSET($AV$5, ROW()-ROW($AY$5),0) -> 322822.73 | BA6: Consumer | BB6: 1093 | BC6: 3072 | BD6: 936 | BE6: 5101 | BG6: =OFFSET($BA$6, ROW()-ROW($BG$6),0) -> Consumer | BH6: =OFFSET($BB$6, ROW()-ROW($BH$6),0) -> 1093 | BI6: =OFFSET($BC$6, ROW()-ROW($BI$6),0) -> 3072 | BJ6: =OFFSET($BD$6, ROW()-ROW($BJ$6),0) -> 936 | BK6: =OFFSET($BE$6, ROW()-ROW($BK$6),0) -> 5101 | BM6: Central | BN6: 1188 | BO6: 661 | BP6: 428 | BQ6: 2277 | BS6: 2016 | BT6: 459436.01 | BW6: 2016 | BX6: 459436.01 | CA6: East | CB6: 0.29604591
A7: West | B7: 710219.68 | C7: =OFFSET($A$4, ROW()-ROW($C$4),0) -> West | D7: =OFFSET($B$4, ROW()-ROW($D$4),0) -> 710219.68 | I7: =OFFSET($G$4, ROW()-ROW($I$4),0) -> 0 | J7: =OFFSET($H$4, ROW()-ROW($J$4),0) -> 0 | L7: Mar | M7: 55205.797 | N7: 32339.318 | O7: 51165.059 | P7: 58863.413 | Q7: 197573.59 | R7: =OFFSET($L$5, ROW()-ROW($R$5),0) -> Mar | S7: =OFFSET($M$5, ROW()-ROW($S$5),0) -> 55205.797 | T7: =OFFSET($N$5, ROW()-ROW($T$5),0) -> 32339.318 | U7: =OFFSET($O$5, ROW()-ROW($U$5),0) -> 51165.059 | V7: =OFFSET($P$5, ROW()-ROW($V$5),0) -> 58863.413 | W7: =OFFSET($Q$5, ROW()-ROW($W$5),0) -> 197573.59 | AB7: =OFFSET($Y$4, ROW()-ROW($AB$4),0) -> 0 | AC7: =OFFSET($Z$4, ROW()-ROW($AC$4),0) -> 0 | AE7: West | AF7: 3140 | AG7: =OFFSET($AE$4, ROW()-ROW($AG$4),0) -> West | AH7: =OFFSET($AF$4, ROW()-ROW($AH$4),0) -> 3140 | AJ7: Home Office | AK7: 0.18791743 | AL7: =OFFSET($AJ$5, ROW()-ROW($AL$5),0) -> Home Office | AM7: =OFFSET($AK$5, ROW()-ROW($AM$5),0) -> 0.18791743 | AO7: Technology | AP7: 1813 | AU7: Storage | AV7: 219343.39 | AX7: =OFFSET($AU$5, ROW()-ROW($AX$5),0) -> Storage | AY7: =OFFSET($AV$5, ROW()-ROW($AY$5),0) -> 219343.39 | BA7: Corporate | BB7: 628 | BC7: 1783 | BD7: 542 | BE7: 2953 | BG7: =OFFSET($BA$6, ROW()-ROW($BG$6),0) -> Corporate | BH7: =OFFSET($BB$6, ROW()-ROW($BH$6),0) -> 628 | BI7: =OFFSET($BC$6, ROW()-ROW($BI$6),0) -> 1783 | BJ7: =OFFSET($BD$6, ROW()-ROW($BJ$6),0) -> 542 | BK7: =OFFSET($BE$6, ROW()-ROW($BK$6),0) -> 2953 | BM7: East | BN7: 1444 | BO7: 850 | BP7: 491 | BQ7: 2785 | BS7: 2017 | BT7: 600192.55 | BW7: 2017 | BX7: 600192.55 | CA7: South | CB7: 0.1720739
A8: Grand Total | B8: 2261536.8 | C8: =OFFSET($A$4, ROW()-ROW($C$4),0) -> Grand Total | D8: =OFFSET($B$4, ROW()-ROW($D$4),0) -> 2261536.8 | L8: Apr | M8: 27906.855 | N8: 34154.468 | O8: 38679.767 | P8: 35541.91 | Q8: 136283 | R8: =OFFSET($L$5, ROW()-ROW($R$5),0) -> Apr | S8: =OFFSET($M$5, ROW()-ROW($S$5),0) -> 27906.855 | T8: =OFFSET($N$5, ROW()-ROW($T$5),0) -> 34154.468 | U8: =OFFSET($O$5, ROW()-ROW($U$5),0) -> 38679.767 | V8: =OFFSET($P$5, ROW()-ROW($V$5),0) -> 35541.91 | W8: =OFFSET($Q$5, ROW()-ROW($W$5),0) -> 136283 | AE8: Grand Total | AF8: 9800 | AG8: =OFFSET($AE$4, ROW()-ROW($AG$4),0) -> Grand Total | AH8: =OFFSET($AF$4, ROW()-ROW($AH$4),0) -> 9800 | AL8: =OFFSET($AJ$5, ROW()-ROW($AL$5),0) -> 0 | AM8: =OFFSET($AK$5, ROW()-ROW($AM$5),0) -> 0 | AO8: Grand Total | AP8: 9800 | AU8: Tables | AV8: 202810.63 | AX8: =OFFSET($AU$5, ROW()-ROW($AX$5),0) -> Tables | AY8: =OFFSET($AV$5, ROW()-ROW($AY$5),0) -> 202810.63 | BA8: Home Office | BB8: 357 | BC8: 1054 | BD8: 335 | BE8: 1746 | BG8: =OFFSET($BA$6, ROW()-ROW($BG$6),0) -> Home Office | BH8: =OFFSET($BB$6, ROW()-ROW($BH$6),0) -> 357 | BI8: =OFFSET($BC$6, ROW()-ROW($BI$6),0) -> 1054 | BJ8: =OFFSET($BD$6, ROW()-ROW($BJ$6),0) -> 335 | BK8: =OFFSET($BE$6, ROW()-ROW($BK$6),0) -> 1746 | BM8: South | BN8: 831 | BO8: 500 | BP8: 267 | BQ8: 1598 | BS8: 2018 | BT8: 722052.02 | BW8: 2018 | BX8: 722052.02 | CA8: West | CB8: 0.31404295
L9: May | M9: 23644.303 | N9: 29959.53 | O9: 56656.908 | P9: 43825.982 | Q9: 154086.72 | R9: =OFFSET($L$5, ROW()-ROW($R$5),0) -> May | S9: =OFFSET($M$5, ROW()-ROW($S$5),0) -> 23644.303 | T9: =OFFSET($N$5, ROW()-ROW($T$5),0) -> 29959.53 | U9: =OFFSET($O$5, ROW()-ROW($U$5),0) -> 56656.908 | V9: =OFFSET($P$5, ROW()-ROW($V$5),0) -> 43825.982 | W9: =OFFSET($Q$5, ROW()-ROW($W$5),0) -> 154086.72 | AU9: Binders | AV9: 200028.79 | AX9: =OFFSET($AU$5, ROW()-ROW($AX$5),0) -> Binders | AY9: =OFFSET($AV$5, ROW()-ROW($AY$5),0) -> 200028.79 | BA9: Grand Total | BB9: 2078 | BC9: 5909 | BD9: 1813 | BE9: 9800 | BG9: =OFFSET($BA$6, ROW()-ROW($BG$6),0) -> Grand Total | BH9: =OFFSET($BB$6, ROW()-ROW($BH$6),0) -> 2078 | BI9: =OFFSET($BC$6, ROW()-ROW($BI$6),0) -> 5909 | BJ9: =OFFSET($BD$6, ROW()-ROW($BJ$6),0) -> 1813 | BK9: =OFFSET($BE$6, ROW()-ROW($BK$6),0) -> 9800 | BM9: West | BN9: 1638 | BO9: 942 | BP9: 560 | BQ9: 3140 | BS9: Grand Total | BT9: 2261536.8 | BW9: Grand Total | BX9: 2261536.8 | CA9: Grand Total | CB9: 1
L10: Jun | M10: 34322.936 | N10: 23599.374 | O10: 39724.486 | P10: 48190.728 | Q10: 145837.52 | R10: =OFFSET($L$5, ROW()-ROW($R$5),0) -> Jun | S10: =OFFSET($M$5, ROW()-ROW($S$5),0) -> 34322.936 | T10: =OFFSET($N$5, ROW()-ROW($T$5),0) -> 23599.374 | U10: =OFFSET($O$5, ROW()-ROW($U$5),0) -> 39724.486 | V10: =OFFSET($P$5, ROW()-ROW($V$5),0) -> 48190.728 | W10: =OFFSET($Q$5, ROW()-ROW($W$5),0) -> 145837.52 | AU10: Machines | AV10: 189238.63 | AX10: =OFFSET($AU$5, ROW()-ROW($AX$5),0) -> Machines | AY10: =OFFSET($AV$5, ROW()-ROW($AY$5),0) -> 189238.63 | BM10: Grand Total | BN10: 5101 | BO10: 2953 | BP10: 1746 | BQ10: 9800
L11: Jul | M11: 33781.543 | N11: 28608.259 | O11: 38320.783 | P11: 44825.104 | Q11: 145535.69 | R11: =OFFSET($L$5, ROW()-ROW($R$5),0) -> Jul | S11: =OFFSET($M$5, ROW()-ROW($S$5),0) -> 33781.543 | T11: =OFFSET($N$5, ROW()-ROW($T$5),0) -> 28608.259 | U11: =OFFSET($O$5, ROW()-ROW($U$5),0) -> 38320.783 | V11: =OFFSET($P$5, ROW()-ROW($V$5),0) -> 44825.104 | W11: =OFFSET($Q$5, ROW()-ROW($W$5),0) -> 145535.69 | AU11: Accessories | AV11: 164186.7 | AX11: =OFFSET($AU$5, ROW()-ROW($AX$5),0) -> Accessories | AY11: =OFFSET($AV$5, ROW()-ROW($AY$5),0) -> 164186.7
L12: Aug | M12: 27117.536 | N12: 36818.342 | O12: 30542.2 | P12: 62837.848 | Q12: 157315.93 | R12: =OFFSET($L$5, ROW()-ROW($R$5),0) -> Aug | S12: =OFFSET($M$5, ROW()-ROW($S$5),0) -> 27117.536 | T12: =OFFSET($N$5, ROW()-ROW($T$5),0) -> 36818.342 | U12: =OFFSET($O$5, ROW()-ROW($U$5),0) -> 30542.2 | V12: =OFFSET($P$5, ROW()-ROW($V$5),0) -> 62837.848 | W12: =OFFSET($Q$5, ROW()-ROW($W$5),0) -> 157315.93 | AE12: Row Labels | AF12: Count of Customer ID | AU12: Copiers | AV12: 146248.09 | AX12: =OFFSET($AU$5, ROW()-ROW($AX$5),0) -> Copiers | AY12: =OFFSET($AV$5, ROW()-ROW($AY$5),0) -> 146248.09
L13: Sep | M13: 81623.527 | N13: 63133.606 | O13: 69193.391 | P13: 86152.888 | Q13: 300103.41 | R13: =OFFSET($L$5, ROW()-ROW($R$5),0) -> Sep | S13: =OFFSET($M$5, ROW()-ROW($S$5),0) -> 81623.527 | T13: =OFFSET($N$5, ROW()-ROW($T$5),0) -> 63133.606 | U13: =OFFSET($O$5, ROW()-ROW($U$5),0) -> 69193.391 | V13: =OFFSET($P$5, ROW()-ROW($V$5),0) -> 86152.888 | W13: =OFFSET($Q$5, ROW()-ROW($W$5),0) -> 300103.41 | AE13: Central | AF13: 2277 | AU13: Bookcases | AV13: 113813.2 | AX13: =OFFSET($AU$5, ROW()-ROW($AX$5),0) -> Bookcases | AY13: =OFFSET($AV$5, ROW()-ROW($AY$5),0) -> 113813.2
L14: Oct | M14: 31453.393 | N14: 31011.738 | O14: 59583.033 | P14: 77448.131 | Q14: 199496.29 | R14: =OFFSET($L$5, ROW()-ROW($R$5),0) -> Oct | S14: =OFFSET($M$5, ROW()-ROW($S$5),0) -> 31453.393 | T14: =OFFSET($N$5, ROW()-ROW($T$5),0) -> 31011.738 | U14: =OFFSET($O$5, ROW()-ROW($U$5),0) -> 59583.033 | V14: =OFFSET($P$5, ROW()-ROW($V$5),0) -> 77448.131 | W14: =OFFSET($Q$5, ROW()-ROW($W$5),0) -> 199496.29 | AE14: East | AF14: 2785 | AU14: Appliances | AV14: 104618.4 | AX14: =OFFSET($AU$5, ROW()-ROW($AX$5),0) -> Appliances | AY14: =OFFSET($AV$5, ROW()-ROW($AY$5),0) -> 104618.4
L15: Nov | M15: 77907.661 | N15: 75249.4 | O15: 79066.496 | P15: 117938.16 | Q15: 350161.71 | R15: =OFFSET($L$5, ROW()-ROW($R$5),0) -> Nov | S15: =OFFSET($M$5, ROW()-ROW($S$5),0) -> 77907.661 | T15: =OFFSET($N$5, ROW()-ROW($T$5),0) -> 75249.4 | U15: =OFFSET($O$5, ROW()-ROW($U$5),0) -> 79066.496 | V15: =OFFSET($P$5, ROW()-ROW($V$5),0) -> 117938.16 | W15: =OFFSET($Q$5, ROW()-ROW($W$5),0) -> 350161.71 | AE15: South | AF15: 1598 | AG15: =GETPIVOTDATA("Customer ID",$AE$3)/GETPIVOTDATA("Customer ID",$AE$12) -> 1 | AU15: Furnishings | AV15: 89212.018 | AX15: =OFFSET($AU$5, ROW()-ROW($AX$5),0) -> Furnishings | AY15: =OFFSET($AV$5, ROW()-ROW($AY$5),0) -> 89212.018
L16: Dec | M16: 68167.058 | N16: 74543.601 | O16: 95739.121 | P16: 83030.389 | Q16: 321480.17 | R16: =OFFSET($L$5, ROW()-ROW($R$5),0) -> Dec | S16: =OFFSET($M$5, ROW()-ROW($S$5),0) -> 68167.058 | T16: =OFFSET($N$5, ROW()-ROW($T$5),0) -> 74543.601 | U16: =OFFSET($O$5, ROW()-ROW($U$5),0) -> 95739.121 | V16: =OFFSET($P$5, ROW()-ROW($V$5),0) -> 83030.389 | W16: =OFFSET($Q$5, ROW()-ROW($W$5),0) -> 321480.17 | AE16: West | AF16: 3140 | AU16: Paper | AV16: 76828.304 | AX16: =OFFSET($AU$5, ROW()-ROW($AX$5),0) -> Paper | AY16: =OFFSET($AV$5, ROW()-ROW($AY$5),0) -> 76828.304
G17: Row Labels | H17: Sum of Sales | L17: Grand Total | M17: 479856.21 | N17: 459436.01 | O17: 600192.55 | P17: 722052.02 | Q17: 2261536.8 | R17: =OFFSET($L$5, ROW()-ROW($R$5),0) -> Grand Total | S17: =OFFSET($M$5, ROW()-ROW($S$5),0) -> 479856.21 | T17: =OFFSET($N$5, ROW()-ROW($T$5),0) -> 459436.01 | U17: =OFFSET($O$5, ROW()-ROW($U$5),0) -> 600192.55 | V17: =OFFSET($P$5, ROW()-ROW($V$5),0) -> 722052.02 | W17: =OFFSET($Q$5, ROW()-ROW($W$5),0) -> 2261536.8 | AE17: Grand Total | AF17: 9800 | AU17: Supplies | AV17: 46420.308 | AX17: =OFFSET($AU$5, ROW()-ROW($AX$5),0) -> Supplies | AY17: =OFFSET($AV$5, ROW()-ROW($AY$5),0) -> 46420.308
G18: Central | H18: 492646.91 | AU18: Art | AV18: 26705.41 | AX18: =OFFSET($AU$5, ROW()-ROW($AX$5),0) -> Art | AY18: =OFFSET($AV$5, ROW()-ROW($AY$5),0) -> 26705.41
G19: East | H19: 669518.73 | S19: =GETPIVOTDATA("Sales",$L$3,"Years (Order Date)",2015) -> 479856.21 | AU19: Envelopes | AV19: 16128.046 | AX19: =OFFSET($AU$5, ROW()-ROW($AX$5),0) -> Envelopes | AY19: =OFFSET($AV$5, ROW()-ROW($AY$5),0) -> 16128.046
G20: South | H20: 389151.46 | S20: =GETPIVOTDATA("Sales",$L$3,"Years (Order Date)",2016) -> 459436.01 | AU20: Labels | AV20: 12347.726 | AX20: =OFFSET($AU$5, ROW()-ROW($AX$5),0) -> Labels | AY20: =OFFSET($AV$5, ROW()-ROW($AY$5),0) -> 12347.726
G21: West | H21: 710219.68 | AU21: Fasteners | AV21: 3001.96 | AX21: =OFFSET($AU$5, ROW()-ROW($AX$5),0) -> Fasteners | AY21: =OFFSET($AV$5, ROW()-ROW($AY$5),0) -> 3001.96
G22: Grand Total | H22: 2261536.8 | Y22: Sum of Sales | Z22: Column Labels | AU22: Grand Total | AV22: 2261536.8 | AX22: =OFFSET($AU$5, ROW()-ROW($AX$5),0) -> Grand Total | AY22: =OFFSET($AV$5, ROW()-ROW($AY$5),0) -> 2261536.8
Y23: Row Labels | Z23: Furniture | AA23: Office Supplies | AB23: Technology
Y24: Accessories | AB24: 164186.7
Y25: Appliances | AA25: 104618.4
Y26: Art | AA26: 26705.41
Y27: Binders | AA27: 200028.79
Y28: Bookcases | Z28: 113813.2
Y29: Chairs | Z29: 322822.73
Y30: Copiers | AB30: 146248.09
Y31: Envelopes | AA31: 16128.046
Y32: Fasteners | AA32: 3001.96
G33: Row Labels | H33: Sum of Sales | Y33: Furnishings | Z33: 89212.018
G34: Central | H34: 492646.91 | I34: =GETPIVOTDATA("Sales",$G$17)/GETPIVOTDATA("Sales",$G$33) -> 1 | Y34: Labels | AA34: 12347.726
G35: East | H35: 669518.73 | Y35: Machines | AB35: 189238.63
G36: South | H36: 389151.46 | Y36: Paper | AA36: 76828.304
G37: West | H37: 710219.68 | Y37: Phones | AB37: 327782.45
G38: Grand Total | H38: 2261536.8 | Y38: Storage | AA38: 219343.39
Y39: Supplies | AA39: 46420.308
Y40: Tables | Z40: 202810.63

Sheet Dashboard
S2: Total Sales | T2: Avg yearly sales | V2: Sales by region | W2: No. of customers | Y2: Customers by region
S3: =GETPIVOTDATA("Sales",PivotTables!$A$3) -> 2261536.8 | T3: =AVERAGE(GETPIVOTDATA("Sales",PivotTables!$BS$4,"Years (Order Date)",2015),GETPIVOTDATA("Sales",PivotTables!$BS$4,"Years (Order Date)",2016),GETPIVOTDATA("Sales",PivotTables!$BS$4,"Years (Order Date)",2017),GETPIVOTDATA("Sales",PivotTables!$BS$4,"Years (Order Date)",2018)) -> 565384.2 | V3: =PivotTables!I34 -> 1 | W3: =GETPIVOTDATA("Customer ID",PivotTables!$BA$4) -> 9800 | Y3: =PivotTables!AG15 -> 1
